<?xml version="1.0" encoding="utf-8"?>
<mujoco>
	<!--The compiler sets global interpreter params (i.e. local coordinates -->
	<compiler angle="radian" coordinate="local" meshdir="../stls/fetch" texturedir="../textures"></compiler>
        <!-- Since we are working with trajectories this makes sense -->
	<option timestep="0.002">
		<flag warmstart="enable"></flag>
	</option>

	<include file="shared.xml"></include>
	
	<!-- Constructing the Kinematic Tree via nesting -->
	<worldbody>
		<geom name="floor0" pos="0.8 0.75 0" size="0.85 0.7 1" type="plane" condim="3" material="floor_mat"></geom>

		<include file="robot.xml"></include>
		
		<body pos="1.3 0.75 0.2" name="table0">
			<geom size="0.25 0.35 0.2" type="box" mass="2000" material="table_mat"></geom>
		</body>
		
		<body name="box00" pos="1.2 0.66 0.3">
			<joint name="box00:joint" type="slide" axis="0 0 1" range="-0.001 0" damping="0.001"></joint>
			<geom size="0.025 0.025 0.01" type="box" condim="3" name="box00" material="block_mat" mass="2000"></geom>
			<site name="box00" pos="0 0 0" size="0.02 0.02 0.005" rgba="1 0 0 1" type="sphere"></site>
                </body>
		<body name="box01" pos="1.2 0.76 0.3">
			<joint name="box01:joint" type="slide" axis="0 0 1" range="-0.001 0" damping="0.001"></joint>
			<geom size="0.025 0.025 0.01" type="box" condim="3" name="box01" material="block_mat" mass="2000"></geom>
			<site name="box01" pos="0 0 0" size="0.02 0.02 0.005" rgba="1 0 0 1" type="sphere"></site>
                </body>
		<body name="box02" pos="1.2 0.86 0.3">
			<geom size="0.025 0.025 0.01" type="box" condim="3" name="box02" material="block_mat" mass="2000"></geom>
			<joint name="box02:joint" type="slide" axis="0 0 1" range="-0.001 0" damping="0.001"></joint>
			<site name="box02" pos="0 0 0" size="0.02 0.02 0.005" rgba="1 0 0 1" type="sphere"></site>
                </body>
		<body name="box10" pos="1.3 0.66 0.3">
			<joint name="box10:joint" type="slide" axis="0 0 1" range="-0.001 0" damping="0.001"></joint>
			<geom size="0.025 0.025 0.01" type="box" condim="3" name="box10" material="block_mat" mass="2000"></geom>
			<site name="box10" pos="0 0 0" size="0.02 0.02 0.005" rgba="1 0 0 1" type="sphere"></site>
                </body>
		<body name="box11" pos="1.3 0.76 0.3">
			<joint name="box11:joint" type="slide" axis="0 0 1" range="-0.001 0" damping="0.001"></joint>
			<geom size="0.025 0.025 0.01" type="box" condim="3" name="box11" material="block_mat" mass="2000"></geom>
			<site name="box11" pos="0 0 0" size="0.02 0.02 0.005" rgba="1 0 0 1" type="sphere"></site>
                </body>
		<body name="box12" pos="1.3 0.86 0.3">
			<joint name="box12:joint" type="slide" axis="0 0 1" range="-0.001 0" damping="0.001"></joint>
			<geom size="0.025 0.025 0.01" type="box" condim="3" name="box12" material="block_mat" mass="2000"></geom>
			<site name="box12" pos="0 0 0" size="0.02 0.02 0.005" rgba="1 0 0 1" type="sphere"></site>
                </body>
		<body name="box20" pos="1.4 0.66 0.3">
			<joint name="box20:joint" type="slide" axis="0 0 1" range="-0.001 0" damping="0.001"></joint>
			<geom size="0.025 0.025 0.01" type="box" condim="3" name="box20" material="block_mat" mass="2000"></geom>
			<site name="box20" pos="0 0 0" size="0.02 0.02 0.005" rgba="1 0 0 1" type="sphere"></site>
                </body>
		<body name="box21" pos="1.4 0.76 0.3">
			<joint name="box21:joint" type="slide" axis="0 0 1" range="-0.001 0" damping="0.001"></joint>
			<geom size="0.025 0.025 0.01" type="box" condim="3" name="box21" material="block_mat" mass="2000"></geom>
			<site name="box21" pos="0 0 0" size="0.02 0.02 0.005" rgba="1 0 0 1" type="sphere"></site>
                </body>
		<body name="box22" pos="1.4 0.86 0.3">
			<joint name="box22:joint" type="slide" axis="0 0 1" range="-0.001 0" damping="0.001"></joint>
			<geom size="0.025 0.025 0.01" type="box" condim="3" name="box22" material="block_mat" mass="2000"></geom>
			<site name="box22" pos="0 0 0" size="0.02 0.02 0.005" rgba="1 0 0 1" type="sphere"></site>
                </body>

		<light directional="true" ambient="0.2 0.2 0.2" diffuse="0.8 0.8 0.8" specular="0.3 0.3 0.3" castshadow="false" pos="0 0 4" dir="0 0 -1" name="light0"></light>
	</worldbody>
	
	<!-- These are the constraints on the fingers -->
	<actuator>
		<position ctrllimited="true" ctrlrange="0 0.2" joint="robot0:l_gripper_finger_joint" kp="30000" name="robot0:l_gripper_finger_joint" user="1"></position>
		<position ctrllimited="true" ctrlrange="0 0.2" joint="robot0:r_gripper_finger_joint" kp="30000" name="robot0:r_gripper_finger_joint" user="1"></position>
	</actuator>
</mujoco>
